Workbook

Sheet Checklist
A1: CHECKLIST HỌC IoT THEO NGÀY — SMART HOME
A2: Nhập ngày bắt đầu ở ô vàng bên dưới để tự tính ngày cho từng buổi học. Chọn trạng thái ở cột F (danh sách thả xuống).
A3: Ngày bắt đầu: | B3: 46257 | D3: Tổng số ngày trong lộ trình: | F3: 57
A5: Ngày # | B5: Ngày (dự kiến) | C5: Giai đoạn | D5: Việc cần làm hôm nay | E5: Tài nguyên / Ghi chú | F5: Trạng thái
A6: 1 | B6: =$B$3+(A6-1) -> 46257 | C6: GĐ0 - Trải nghiệm nhanh | D6: Cài Home Assistant + add-on ESPHome; viết YAML cho ESP32 + DHT22; flash và xem thiết bị xuất hiện trên dashboard | E6: ESPHome.io, HomeAssistant.io | F6: Đang làm | G6: chưa mua thiết bị học
A7: 2 | B7: =$B$3+(A7-1) -> 46258 | C7: GĐ1 - Phần cứng & Firmware | D7: Ôn GPIO digital/analog, PWM, ADC trên ESP32 | E7: Kênh E-smart - Khóa học ESP32 căn bản
A8: 3 | B8: =$B$3+(A8-1) -> 46259 | C8: GĐ1 - Phần cứng & Firmware | D8: Học và lắp cảm biến chuyển động PIR
A9: 4 | B9: =$B$3+(A9-1) -> 46260 | C9: GĐ1 - Phần cứng & Firmware | D9: Học và lắp cảm biến ánh sáng (quang trở LDR)
A10: 5 | B10: =$B$3+(A10-1) -> 46261 | C10: GĐ1 - Phần cứng & Firmware | D10: Học và lắp cảm biến cửa từ (reed switch)
A11: 6 | B11: =$B$3+(A11-1) -> 46262 | C11: GĐ1 - Phần cứng & Firmware | D11: Học điều khiển module relay
A12: 7 | B12: =$B$3+(A12-1) -> 46263 | C12: GĐ1 - Phần cứng & Firmware | D12: Học điều khiển servo motor
A13: 8 | B13: =$B$3+(A13-1) -> 46264 | C13: GĐ1 - Phần cứng & Firmware | D13: Hiểu ngắt (interrupt) và timer trên ESP32 | E13: Kênh E-smart - Lập trình ESP32
A14: 9 | B14: =$B$3+(A14-1) -> 46265 | C14: GĐ1 - Phần cứng & Firmware | D14: Tự viết code đọc đa cảm biến, không copy nguyên code mẫu
A15: 10 | B15: =$B$3+(A15-1) -> 46266 | C15: GĐ1 - Phần cứng & Firmware | D15: Demo: lắp mạch đèn tự động (LDR + PIR + relay) - phần cứng
A16: 11 | B16: =$B$3+(A16-1) -> 46267 | C16: GĐ1 - Phần cứng & Firmware | D16: Demo: hoàn thiện code và kiểm thử đèn tự động
A17: 12 | B17: =$B$3+(A17-1) -> 46268 | C17: GĐ2 - Giao thức kết nối | D17: Ôn lại kiến thức MQTT đã học (paho-mqtt)
A18: 13 | B18: =$B$3+(A18-1) -> 46269 | C18: GĐ2 - Giao thức kết nối | D18: Học QoS (0/1/2) và ý nghĩa từng mức
A19: 14 | B19: =$B$3+(A19-1) -> 46270 | C19: GĐ2 - Giao thức kết nối | D19: Học Retained message và Last Will and Testament (LWT)
A20: 15 | B20: =$B$3+(A20-1) -> 46271 | C20: GĐ2 - Giao thức kết nối | D20: Tự dựng MQTT broker (Mosquitto Docker hoặc HiveMQ Cloud)
A21: 16 | B21: =$B$3+(A21-1) -> 46272 | C21: GĐ2 - Giao thức kết nối | D21: Thiết kế cấu trúc topic chuẩn cho nhà thông minh
A22: 17 | B22: =$B$3+(A22-1) -> 46273 | C22: GĐ2 - Giao thức kết nối | D22: Xem playlist Điều khiển thiết bị bằng Bluetooth | E22: Kênh E-smart
A23: 18 | B23: =$B$3+(A23-1) -> 46274 | C23: GĐ2 - Giao thức kết nối | D23: Demo: 2 ESP32 giao tiếp qua MQTT (gửi cảm biến + nhận lệnh)
A24: 19 | B24: =$B$3+(A24-1) -> 46275 | C24: GĐ3 - Backend/Cloud | D24: Viết server subscribe MQTT broker (bắt đầu) | E24: Node.js/Express hoặc Python/FastAPI
A25: 20 | B25: =$B$3+(A25-1) -> 46276 | C25: GĐ3 - Backend/Cloud | D25: Viết server subscribe MQTT broker (hoàn thiện)
A26: 21 | B26: =$B$3+(A26-1) -> 46277 | C26: GĐ3 - Backend/Cloud | D26: Lưu trạng thái thiết bị vào database (PostgreSQL/MongoDB)
A27: 22 | B27: =$B$3+(A27-1) -> 46278 | C27: GĐ3 - Backend/Cloud | D27: Tìm hiểu time-series database (InfluxDB) cho dữ liệu cảm biến
A28: 23 | B28: =$B$3+(A28-1) -> 46279 | C28: GĐ3 - Backend/Cloud | D28: Xây REST API - bật/tắt thiết bị
A29: 24 | B29: =$B$3+(A29-1) -> 46280 | C29: GĐ3 - Backend/Cloud | D29: Xây REST API - lấy lịch sử dữ liệu
A30: 25 | B30: =$B$3+(A30-1) -> 46281 | C30: GĐ3 - Backend/Cloud | D30: Thêm WebSocket đẩy dữ liệu realtime (bắt đầu)
A31: 26 | B31: =$B$3+(A31-1) -> 46282 | C31: GĐ3 - Backend/Cloud | D31: Thêm WebSocket đẩy dữ liệu realtime (hoàn thiện)
A32: 27 | B32: =$B$3+(A32-1) -> 46283 | C32: GĐ3 - Backend/Cloud | D32: Demo: test toàn bộ API, log lịch sử nhiệt độ/độ ẩm
A33: 28 | B33: =$B$3+(A33-1) -> 46284 | C33: GĐ4 - Frontend/Dashboard | D33: Dựng khung dashboard React/Vue
A34: 29 | B34: =$B$3+(A34-1) -> 46285 | C34: GĐ4 - Frontend/Dashboard | D34: Hiển thị trạng thái thiết bị theo thời gian thực
A35: 30 | B35: =$B$3+(A35-1) -> 46286 | C35: GĐ4 - Frontend/Dashboard | D35: Kết nối WebSocket từ Giai đoạn 3
A36: 31 | B36: =$B$3+(A36-1) -> 46287 | C36: GĐ4 - Frontend/Dashboard | D36: Vẽ biểu đồ nhiệt độ/độ ẩm (Chart.js/Recharts)
... A47: 42 | B47: =$B$3+(A47-1) -> 46298 | C47: GĐ6 - Automation & AI/Voice | D47: (Tùy chọn) Thử Node-RED cho automation kéo-thả
A48: 43 | B48: =$B$3+(A48-1) -> 46299 | C48: GĐ6 - Automation & AI/Voice | D48: Xem playlist Chatbot xiaozhi (phần 1) | E48: Kênh E-smart
A49: 44 | B49: =$B$3+(A49-1) -> 46300 | C49: GĐ6 - Automation & AI/Voice | D49: Xem playlist Chatbot xiaozhi (phần 2) | E49: Kênh E-smart
A50: 45 | B50: =$B$3+(A50-1) -> 46301 | C50: GĐ6 - Automation & AI/Voice | D50: Xem playlist Lập trình ESP32 bằng ChatGPT | E50: Kênh E-smart
A51: 46 | B51: =$B$3+(A51-1) -> 46302 | C51: GĐ6 - Automation & AI/Voice | D51: (Tùy chọn) Thử tích hợp một lệnh điều khiển bằng giọng nói
...

Sheet TongQuan
A1: TỔNG QUAN TIẾN ĐỘ
A2: Bảng này tự cập nhật dựa trên cột Trạng thái ở sheet Checklist.
A4: Giai đoạn | B4: Tổng số ngày | C4: Đã hoàn thành | D4: % hoàn thành
A5: GĐ0 - Trải nghiệm nhanh | B5: =COUNTIF(Checklist!$C$6:$C$62,A5) -> 1 | C5: =COUNTIFS(Checklist!$C$6:$C$62,A5,Checklist!$F$6:$F$62,"Hoàn thành") -> 0 | D5: =IFERROR(C5/B5,0) -> 0
A6: GĐ1 - Phần cứng & Firmware | B6: =COUNTIF(Checklist!$C$6:$C$62,A6) -> 10 | C6: =COUNTIFS(Checklist!$C$6:$C$62,A6,Checklist!$F$6:$F$62,"Hoàn thành") -> 0 | D6: =IFERROR(C6/B6,0) -> 0
A7: GĐ2 - Giao thức kết nối | B7: =COUNTIF(Checklist!$C$6:$C$62,A7) -> 7 | C7: =COUNTIFS(Checklist!$C$6:$C$62,A7,Checklist!$F$6:$F$62,"Hoàn thành") -> 0 | D7: =IFERROR(C7/B7,0) -> 0
A8: GĐ3 - Backend/Cloud | B8: =COUNTIF(Checklist!$C$6:$C$62,A8) -> 9 | C8: =COUNTIFS(Checklist!$C$6:$C$62,A8,Checklist!$F$6:$F$62,"Hoàn thành") -> 0 | D8: =IFERROR(C8/B8,0) -> 0
A9: GĐ4 - Frontend/Dashboard | B9: =COUNTIF(Checklist!$C$6:$C$62,A9) -> 9 | C9: =COUNTIFS(Checklist!$C$6:$C$62,A9,Checklist!$F$6:$F$62,"Hoàn thành") -> 0 | D9: =IFERROR(C9/B9,0) -> 0
A10: GĐ5 - Bảo mật | B10: =COUNTIF(Checklist!$C$6:$C$62,A10) -> 4 | C10: =COUNTIFS(Checklist!$C$6:$C$62,A10,Checklist!$F$6:$F$62,"Hoàn thành") -> 0 | D10: =IFERROR(C10/B10,0) -> 0
A11: GĐ6 - Automation & AI/Voice | B11: =COUNTIF(Checklist!$C$6:$C$62,A11) -> 8 | C11: =COUNTIFS(Checklist!$C$6:$C$62,A11,Checklist!$F$6:$F$62,"Hoàn thành") -> 0 | D11: =IFERROR(C11/B11,0) -> 0
A12: GĐ7 - Capstone | B12: =COUNTIF(Checklist!$C$6:$C$62,A12) -> 9 | C12: =COUNTIFS(Checklist!$C$6:$C$62,A12,Checklist!$F$6:$F$62,"Hoàn thành") -> 0 | D12: =IFERROR(C12/B12,0) -> 0
A13: TỔNG CỘNG | B13: =SUM(B5:B12) -> 57 | C13: =SUM(C5:C12) -> 0 | D13: =IFERROR(C13/B13,0) -> 0
